<?xml version="1.0"?>
<robot xmlns:xacro="http://www.ros.org/wiki/xacro">
    
    <xacro:macro name="wheel_v0" params="prefix parent *joint_origin *joint_axis">
        <joint name="${prefix}_wheel_joint" type="continuous">
            <xacro:insert_block name="joint_origin" />
            <parent link="${parent}" />
            <child link="${prefix}_wheel_link" />
                <limit effort="1.5" velocity="20" />
            <xacro:insert_block name="joint_axis"/>
        </joint>

        <link name="${prefix}_wheel_link">
            <visual>
                <geometry>
                    <mesh filename="package://rover_description/meshes/STL/wheel/wheel_right.stl" />
                </geometry>
            </visual>
            <collision>
                <geometry>
                    <mesh filename="package://rover_description/meshes/STL/wheel/wheel_right.stl" />
                </geometry>
            </collision>
        </link>
    </xacro:macro>
</robot>
